## 什么是异常

程序运行可能会产生运行时错误，这是由操作决定的。那么如何处理这种错误，如何检测到这种错误的发生就成了问题。如果可以检测到这种错误，我们就可以使用特定的代码去处理。

提供异常就是为了处理上面的问题。

**基本思想：**

让一个函数在发现了自己无法处理的错误时抛出（throw）一个异常，然后它的（直接或者间接）调用者能够处理这个问题。让问题检测和问题处理分隔开来

## 为什么使用异常

如果不使用异常，程序的 **健壮性** 会减弱。比如遇到`a / 0`这样的错误，程序会自动退出。但是如果使用了异常，我们就可以检测出这种错误并抛出异常，然后用专门的处理程序处理。这样就不会使程序崩溃。

## 除数案例

```c++
#include <iostream>
#include <stdexcept>

//除数不能为0
int func(int a, int b)
{
    if (b == 0)
        throw "error!"; //抛出异常(此处抛出的异常类型为 const char* )

    std::cout << "这条语句不会执行" << std::endl; //如果抛出了异常,直接跳转到catch那,后面的语句不会再被执行
}

int main(int argc, char* argv[])
{
    float res = 0;
 
    try {
        res = func(1, 0); //检测在try块中是否有异常
    } catch(const char* error) { //捕捉异常并执行处理程序
        std::cout << error << std::endl;
    }

    return 0;
}
```

```c++
root@iZwz9eojvzsrz78f673t51Z:/home/code# ./main 
error!
```

**特殊形式**

```c++
try
{
    语句块
}
catch（...） //可以捕捉任意抛出的异常
{
    语句块
}
```

## 抛出一个类型为一个类对象

```c++
#include <iostream>
#include <stdexcept>

class Student 
{
public:
    Student() : m_name("") { 
        std::cout << "构造函数调用" << std::endl;
    }
    Student(const Student& student) : m_name(student.m_name) {
        std::cout << "拷贝构造函数调用" << std::endl;
    }
    ~Student() {
        std::cout << "析构函数调用" << std::endl;
    }
    std::string GetName() const {
        return m_name;
    }

private:
    std::string m_name;
};

void ShowName(const Student& student)
{
    if ("" == student.GetName()) 
        throw(student);
    std::cout << student.GetName() << std::endl; //const对象才可以调用const函数
}

int main(int argc, char* argv[])
{
    Student s;
    
    try {
        ShowName(s);
    } catch(const Student) { //捕捉异常并执行处理程序
        std::cout << "出错, 学生名字为空" << std::endl;
    }

    return 0;
}
```

```c++
构造函数调用
拷贝构造函数调用
拷贝构造函数调用
出错, 学生名字为空
析构函数调用
析构函数调用
析构函数调用
```

我们发现调用了两次拷贝构造函数，这是因为`throw`操作会发生两次拷贝操作

- 第一次是在`throw`时，将 **抛出对象** 复制到一个 **临时对象** （这一步是必须的）
- 第二次是因为`catch`处使用对象接收，那么需要再从 **临时对象** 复制到 **catch的形参变量** 中
- 因此也得出一个结论，我们这个类对象是需要能够被复制的
- 如果你在`catch`中使用 **引用** 来接收参数，那么不需要第二次复制，即形参的引用指向临时变量

## 使用C++提供的运行时错误异常类 std::runtime_error

### 简单介绍

> In addition, the following standard exception types are derived from `std::runtime_error`:
>
> - `std::range_error`
> - `std::overflow_error`
> - `std::underflow_error`
> - ...

```c++
runtime_error( const std::string& what_arg );
runtime_error( const char* what_arg );					    (since C++11)
runtime_error( const runtime_error& other );				(until C++11)
runtime_error( const runtime_error& other ) noexcept;		 (since C++11)
```

```c++
virtual const char* what() const throw(); 	(until C++11)
virtual const char* what() const noexcept; 	(since C++11)
```

### 案例改写

```c++
#include <iostream>
#include <stdexcept>

class Student 
{
public:
    Student() : m_name("") { 
        std::cout << "构造函数调用" << std::endl;
    }
    Student(const Student& student) : m_name(student.m_name) {
        std::cout << "拷贝构造函数调用" << std::endl;
    }
    ~Student() {
        std::cout << "析构函数调用" << std::endl;
    }
    std::string GetName() const {
        return m_name;
    }

private:
    std::string m_name;
};

void ShowName(const Student& student)
{
    if ("" == student.GetName()) {
        throw std::runtime_error("The name is empty!");
    }
        
    std::cout << student.GetName() << std::endl; //const对象才可以调用const函数
}

int main(int argc, char* argv[])
{
    Student s;
    
    try {
        ShowName(s);
    } catch(std::runtime_error err) { //捕捉异常并执行处理程序
        std::cout << err.what() << std::endl;
    }

    return 0;
}
```

```c++
构造函数调用
The name is empty!
析构函数调用
```

## 标准库异常类

![C++  标准库异常类继承层次图](https://syz-picture.oss-cn-shenzhen.aliyuncs.com/0_1307449449A34a.gif)



## 参考

- [(199条消息) C++的异常处理_大黑暗天 的专栏-CSDN博客_c++ 异常处理](https://blog.csdn.net/daheiantian/article/details/6530318?ops_request_misc=%7B%22request%5Fid%22%3A%22164698532516780255257215%22%2C%22scm%22%3A%2220140713.130102334..%22%7D&request_id=164698532516780255257215&biz_id=0&spm=1018.2226.3001.4187)
- [std::runtime_error - cppreference.com](https://en.cppreference.com/w/cpp/error/runtime_error)